2023-06-24 13:33:29,344 [werkzeug] [ERROR] :40: Error on request:
Traceback (most recent call last):
  File "D:\anaconda3\envs\flask\Lib\site-packages\werkzeug\serving.py", line 333, in run_wsgi
    execute(self.server.app)
  File "D:\anaconda3\envs\flask\Lib\site-packages\werkzeug\serving.py", line 320, in execute
    application_iter = app(environ, start_response)
                       ^^^^^^^^^^^^^^^^^^^^^^^^^^^^
  File "D:\anaconda3\envs\flask\Lib\site-packages\flask\app.py", line 2551, in __call__
    return self.wsgi_app(environ, start_response)
           ^^^^^^^^^^^^^^^^^^^^^^^^^^^^^^^^^^^^^^
  File "D:\anaconda3\envs\flask\Lib\site-packages\flask\app.py", line 2531, in wsgi_app
    response = self.handle_exception(e)
               ^^^^^^^^^^^^^^^^^^^^^^^^
  File "D:\anaconda3\envs\flask\Lib\site-packages\flask_cors\extension.py", line 165, in wrapped_function
    return cors_after_request(app.make_response(f(*args, **kwargs)))
                                                ^^^^^^^^^^^^^^^^^^^^
  File "D:\anaconda3\envs\flask\Lib\site-packages\flask\app.py", line 2528, in wsgi_app
    response = self.full_dispatch_request()
               ^^^^^^^^^^^^^^^^^^^^^^^^^^^^
  File "D:\anaconda3\envs\flask\Lib\site-packages\flask\app.py", line 1825, in full_dispatch_request
    rv = self.handle_user_exception(e)
         ^^^^^^^^^^^^^^^^^^^^^^^^^^^^^
  File "D:\anaconda3\envs\flask\Lib\site-packages\flask_cors\extension.py", line 165, in wrapped_function
    return cors_after_request(app.make_response(f(*args, **kwargs)))
                                                ^^^^^^^^^^^^^^^^^^^^
  File "D:\anaconda3\envs\flask\Lib\site-packages\flask\app.py", line 1823, in full_dispatch_request
    rv = self.dispatch_request()
         ^^^^^^^^^^^^^^^^^^^^^^^
  File "D:\anaconda3\envs\flask\Lib\site-packages\flask\app.py", line 1799, in dispatch_request
    return self.ensure_sync(self.view_functions[rule.endpoint])(**view_args)
           ^^^^^^^^^^^^^^^^^^^^^^^^^^^^^^^^^^^^^^^^^^^^^^^^^^^^^^^^^^^^^^^^^
  File "E:\code\VScodeProjects\python\flask\ore_detection_server\app\utils\util.py", line 21, in wrapper
    rv = f(*args, **kwargs)
         ^^^^^^^^^^^^^^^^^^
  File "E:\code\VScodeProjects\python\flask\ore_detection_server\app\api\api_main.py", line 26, in upload
    return res.data
           ^^^^^^^^
  File "E:\code\VScodeProjects\python\flask\ore_detection_server\app\utils\response.py", line 52, in data
    body["data"] = body.pop("_data")
                   ^^^^^^^^^^^^^^^^^
KeyError: '_data'
